Блок try используется для выполнения кода, который может вызвать исключение. Блок catch используется для обработки исключений, которые могут возникнуть в блоке try. Блок finally используется для выполнения кода, который должен быть выполнен независимо от того, возникло исключение или нет.

Блок finally может не выполниться, если программа завершается до его выполнения. Например, если в блоке try возникает исключение, которое не обрабатывается в блоке catch, и это исключение не перехватывается в других блоках try-catch, то программа может завершиться до выполнения блока finally.

Пример из реальной жизни: представьте, что вы готовите торт и у вас есть несколько шагов, которые нужно выполнить. Вы начинаете с шага "взбить яйца", который может вызвать исключение, если яйца не свежие. Если яйца не свежие, вы можете выбросить их и начать заново с шага "взбить яйца". В этом случае блок try будет соответствовать шагу "взбить яйца", блок catch будет обрабатывать исключение "яйца не свежие", а блок finally будет соответствовать шагу "вымыть посуду", который должен быть выполнен независимо от того, возникло исключение или нет.

Вот пример кода, демонстрирующий использование блоков try, catch и finally:

```csharp
try
{
    // Код, который может вызвать исключение
    int number = int.Parse(Console.ReadLine());
    if (number < 0)
    {
        throw new ArgumentOutOfRangeException("number", "Number must be positive");
    }
    // остальной код
}
catch (ArgumentOutOfRangeException ex)
{
    Console.WriteLine($"Error: {ex.Message}");
}
finally
{
    // Код, который всегда выполняется
    Console.WriteLine("Finally block executed");
}

```

В этом примере мы используем блок try для выполнения кода, который может вызвать исключение. Если введенное пользователем число отрицательное, мы генерируем исключение ArgumentOutOfRangeException. Затем мы обрабатываем это исключение в блоке catch, выводя сообщение об ошибке. Наконец, мы всегда выполняем код в блоке finally, независимо от того, возникло исключение или нет.